<?xml version="1.0" ?>
<!-- =================================================================================== -->
<!-- |    This document was autogenerated by xacro from urdf/marvin_CCS_m6.urdf.xacro  | -->
<!-- |    EDITING THIS FILE BY HAND IS NOT RECOMMENDED                                 | -->
<!-- =================================================================================== -->
<robot name="marvin_robot">
  <link name="Base_L">
    <inertial>
      <origin rpy="0 0 0" xyz="0.00032267 4.798E-05 0.04066353"/>
      <mass value="1.1962"/>
      <inertia ixx="0.00107329" ixy="-1.68E-06" ixz="-1.05E-05" iyy="0.00107003" iyz="-3.43E-06" izz="0.00127315"/>
    </inertial>
    <visual>
      <origin rpy="0 0 0" xyz="0 0 0"/>
      <geometry>
        <mesh filename="package://marvin_description/meshes/m6/Base_L.STL"/>
      </geometry>
      <material name="">
        <color rgba="1 0 0 1"/>
      </material>
    </visual>
    <collision>
      <origin rpy="0 0 0" xyz="0 0 0"/>
      <geometry>
        <mesh filename="package://marvin_description/meshes/m6/Base_L.STL"/>
      </geometry>
    </collision>
  </link>
  <link name="Link1_L">
    <inertial>
      <origin rpy="0 0 0" xyz="0.00002347 0.00557150 -0.03075998"/>
      <mass value="1.9705"/>
      <inertia ixx="0.00492293" ixy="0.00000550" ixz="0.00000193" iyy="0.00526513" iyz="0.00033232" izz="0.00188107"/>
    </inertial>
    <visual>
      <origin rpy="0 0 0" xyz="0 0 0"/>
      <geometry>
        <mesh filename="package://marvin_description/meshes/m6/Link1_L.STL"/>
      </geometry>
      <material name="">
        <color rgba="0 1 0 1"/>
      </material>
    </visual>
    <collision>
      <origin rpy="0 0 0" xyz="0 0 0"/>
      <geometry>
        <mesh filename="package://marvin_description/meshes/m6/Link1_L.STL"/>
      </geometry>
    </collision>
  </link>
  <joint name="Joint1_L" type="revolute">
    <origin rpy="0 0 0" xyz="0 0 0.1745"/>
    <parent link="Base_L"/>
    <child link="Link1_L"/>
    <axis xyz="0 0 1"/>
    <limit effort="108" lower="-3.1067" upper="3.1067" velocity="3.1416"/>
  </joint>
  <link name="Link2_L">
    <inertial>
      <origin rpy="0 0 0" xyz="0.00013483 0.06170460 0.00950639"/>
      <mass value="2.24398"/>
      <inertia ixx="0.01194933" ixy="0.00000336" ixz="0.00000091" iyy="0.00361581" iyz="-0.00132804" izz="0.01098356"/>
    </inertial>
    <visual>
      <origin rpy="0 0 0" xyz="0 0 0"/>
      <geometry>
        <mesh filename="package://marvin_description/meshes/m6/Link2_L.STL"/>
      </geometry>
      <material name="">
        <color rgba="0 0 1 1"/>
      </material>
    </visual>
    <collision>
      <origin rpy="0 0 0" xyz="0 0 0"/>
      <geometry>
        <mesh filename="package://marvin_description/meshes/m6/Link2_L.STL"/>
      </geometry>
    </collision>
  </link>
  <joint name="Joint2_L" type="revolute">
    <origin rpy="1.5708 0 0" xyz="0 0 0"/>
    <parent link="Link1_L"/>
    <child link="Link2_L"/>
    <axis xyz="0 0 1"/>
    <limit effort="108" lower="-2.0944" upper="2.0944" velocity="3.1416"/>
  </joint>
  <link name="Link3_L">
    <inertial>
      <origin rpy="0 0 0" xyz="0.00968562 0.00246599 -0.04627302"/>
      <mass value="1.9242"/>
      <inertia ixx="0.00718224" ixy="0.00004413" ixz="0.00089552" iyy="0.00762563" iyz="0.00022096" izz="0.00178597"/>
    </inertial>
    <visual>
      <origin rpy="0 0 0" xyz="0 0 0"/>
      <geometry>
        <mesh filename="package://marvin_description/meshes/m6/Link3_L.STL"/>
      </geometry>
      <material name="">
        <color rgba="1 0 0 1"/>
      </material>
    </visual>
    <collision>
      <origin rpy="0 0 0" xyz="0 0 0"/>
      <geometry>
        <mesh filename="package://marvin_description/meshes/m6/Link3_L.STL"/>
      </geometry>
    </collision>
  </link>
  <joint name="Joint3_L" type="revolute">
    <origin rpy="-1.5708 0 0" xyz="0 0.287 0"/>
    <parent link="Link2_L"/>
    <child link="Link3_L"/>
    <axis xyz="0 0 1"/>
    <limit effort="66" lower="-3.1067" upper="3.1067" velocity="3.1416"/>
  </joint>
  <link name="Link4_L">
    <inertial>
      <origin rpy="0 0 0" xyz="0.00850411 -0.04718223 0.00941509"/>
      <mass value="1.6085"/>
      <inertia ixx="0.00580480" ixy="-0.00066669" ixz="-0.00012722" iyy="0.00223807" iyz="0.00070523" izz="0.00533060"/>
    </inertial>
    <visual>
      <origin rpy="0 0 0" xyz="0 0 0"/>
      <geometry>
        <mesh filename="package://marvin_description/meshes/m6/Link4_L.STL"/>
      </geometry>
      <material name="">
        <color rgba="0 1 0 1"/>
      </material>
    </visual>
    <collision>
      <origin rpy="0 0 0" xyz="0 0 0"/>
      <geometry>
        <mesh filename="package://marvin_description/meshes/m6/Link4_L.STL"/>
      </geometry>
    </collision>
  </link>
  <joint name="Joint4_L" type="revolute">
    <origin rpy="-1.5708 0 3.1416" xyz="0.018 0 0"/>
    <parent link="Link3_L"/>
    <child link="Link4_L"/>
    <axis xyz="0 0 1"/>
    <limit effort="66" lower="-2.5307" upper="1.0472" velocity="3.1416"/>
  </joint>
  <link name="Link5_L">
    <inertial>
      <origin rpy="0 0 0" xyz="0.00051127 0.00101064 -0.11271739"/>
      <mass value="2.0883"/>
      <inertia ixx="0.00626603" ixy="0.00004009" ixz="0.00005338" iyy="0.00564387" iyz="-0.00006193" izz="0.00243632"/>
    </inertial>
    <visual>
      <origin rpy="0 0 0" xyz="0 0 0"/>
      <geometry>
        <mesh filename="package://marvin_description/meshes/m6/Link5_L.STL"/>
      </geometry>
      <material name="">
        <color rgba="0 0 1 1"/>
      </material>
    </visual>
    <collision>
      <origin rpy="0 0 0" xyz="0 0 0"/>
      <geometry>
        <mesh filename="package://marvin_description/meshes/m6/Link5_L.STL"/>
      </geometry>
    </collision>
  </link>
  <joint name="Joint5_L" type="revolute">
    <origin rpy="-1.5708 0 3.1416" xyz="0.018 -0.314 0"/>
    <parent link="Link4_L"/>
    <child link="Link5_L"/>
    <axis xyz="0 0 1"/>
    <limit effort="18" lower="-3.1067" upper="3.1067" velocity="3.1416"/>
  </joint>
  <link name="Link6_L">
    <inertial>
      <origin rpy="0 0 0" xyz="0.00032659 0.00531336 -0.00030182"/>
      <mass value="0.72496"/>
      <inertia ixx="0.00046040" ixy="0.00000189" ixz="0.00000083" iyy="0.00051716" iyz="-0.00000346" izz="0.00042521"/>
    </inertial>
    <visual>
      <origin rpy="0 0 0" xyz="0 0 0"/>
      <geometry>
        <mesh filename="package://marvin_description/meshes/m6/Link6_L.STL"/>
      </geometry>
      <material name="">
        <color rgba="1 0 0 1"/>
      </material>
    </visual>
    <collision>
      <origin rpy="0 0 0" xyz="0 0 0"/>
      <geometry>
        <mesh filename="package://marvin_description/meshes/m6/Link6_L.STL"/>
      </geometry>
    </collision>
  </link>
  <joint name="Joint6_L" type="revolute">
    <origin rpy="1.5708 -1.5708 0" xyz="0 0 0"/>
    <parent link="Link5_L"/>
    <child link="Link6_L"/>
    <axis xyz="0 0 1"/>
    <limit effort="18" lower="-1.0472" upper="1.0472" velocity="3.1416"/>
  </joint>
  <link name="Link7_L">
    <inertial>
      <origin rpy="0 0 0" xyz="-0.00009108 -0.03153255 0.00889371"/>
      <mass value="0.68606"/>
      <inertia ixx="0.00173687" ixy="-0.00000345" ixz="-0.00000116" iyy="0.00089035" iyz="0.00030680" izz="0.00139406"/>
    </inertial>
    <visual>
      <origin rpy="0 0 0" xyz="0 0 0"/>
      <geometry>
        <mesh filename="package://marvin_description/meshes/m6/Link7_L.STL"/>
      </geometry>
      <material name="">
        <color rgba="0 1 0 1"/>
      </material>
    </visual>
    <collision>
      <origin rpy="0 0 0" xyz="0 0 0"/>
      <geometry>
        <mesh filename="package://marvin_description/meshes/m6/Link7_L.STL"/>
      </geometry>
    </collision>
  </link>
  <joint name="Joint7_L" type="revolute">
    <origin rpy="1.5708 -1.5708 0" xyz="0 0 0"/>
    <parent link="Link6_L"/>
    <child link="Link7_L"/>
    <axis xyz="0 0 1"/>
    <limit effort="18" lower="-1.5708" upper="1.5708" velocity="3.1416"/>
  </joint>
  <link name="flange_L"/>
  <joint name="joint_flange_L" type="fixed">
    <origin rpy="1.5708 -1.5708 0" xyz="0.0 -0.088 0.0"/>
    <parent link="Link7_L"/>
    <child link="flange_L"/>
  </joint>
  <link name="Base_R">
    <inertial>
      <origin rpy="0 0 0" xyz="0.00032267 4.798E-05 0.04066353"/>
      <mass value="1.1962"/>
      <inertia ixx="0.00107329" ixy="-1.68E-06" ixz="-1.05E-05" iyy="0.00107003" iyz="-3.43E-06" izz="0.00127315"/>
    </inertial>
    <visual>
      <origin rpy="0 0 0" xyz="0 0 0"/>
      <geometry>
        <mesh filename="package://marvin_description/meshes/m6/Base_R.STL"/>
      </geometry>
      <material name="">
        <color rgba="1 0 0 1"/>
      </material>
    </visual>
    <collision>
      <origin rpy="0 0 0" xyz="0 0 0"/>
      <geometry>
        <mesh filename="package://marvin_description/meshes/m6/Base_R.STL"/>
      </geometry>
    </collision>
  </link>
  <link name="Link1_R">
    <inertial>
      <origin rpy="0 0 0" xyz="0.00002347 0.00557150 -0.03075998"/>
      <mass value="1.9705"/>
      <inertia ixx="0.00492293" ixy="0.00000550" ixz="0.00000193" iyy="0.00526513" iyz="0.00033232" izz="0.00188107"/>
    </inertial>
    <visual>
      <origin rpy="0 0 0" xyz="0 0 0"/>
      <geometry>
        <mesh filename="package://marvin_description/meshes/m6/Link1_R.STL"/>
      </geometry>
      <material name="">
        <color rgba="0 1 0 1"/>
      </material>
    </visual>
    <collision>
      <origin rpy="0 0 0" xyz="0 0 0"/>
      <geometry>
        <mesh filename="package://marvin_description/meshes/m6/Link1_R.STL"/>
      </geometry>
    </collision>
  </link>
  <joint name="Joint1_R" type="revolute">
    <origin rpy="0 0 0" xyz="0 0 0.1745"/>
    <parent link="Base_R"/>
    <child link="Link1_R"/>
    <axis xyz="0 0 1"/>
    <limit effort="108" lower="-3.1067" upper="3.1067" velocity="3.1416"/>
  </joint>
  <link name="Link2_R">
    <inertial>
      <origin rpy="0 0 0" xyz="0.00013483 0.06170460 0.00950639"/>
      <mass value="2.24398"/>
      <inertia ixx="0.01194933" ixy="0.00000336" ixz="0.00000091" iyy="0.00361581" iyz="-0.00132804" izz="0.01098356"/>
    </inertial>
    <visual>
      <origin rpy="0 0 0" xyz="0 0 0"/>
      <geometry>
        <mesh filename="package://marvin_description/meshes/m6/Link2_R.STL"/>
      </geometry>
      <material name="">
        <color rgba="0 0 1 1"/>
      </material>
    </visual>
    <collision>
      <origin rpy="0 0 0" xyz="0 0 0"/>
      <geometry>
        <mesh filename="package://marvin_description/meshes/m6/Link2_R.STL"/>
      </geometry>
    </collision>
  </link>
  <joint name="Joint2_R" type="revolute">
    <origin rpy="1.5708 0 0" xyz="0 0 0"/>
    <parent link="Link1_R"/>
    <child link="Link2_R"/>
    <axis xyz="0 0 1"/>
    <limit effort="108" lower="-2.0944" upper="2.0944" velocity="3.1416"/>
  </joint>
  <link name="Link3_R">
    <inertial>
      <origin rpy="0 0 0" xyz="0.00968562 0.00246599 -0.04627302"/>
      <mass value="1.9242"/>
      <inertia ixx="0.00718224" ixy="0.00004413" ixz="0.00089552" iyy="0.00762563" iyz="0.00022096" izz="0.00178597"/>
    </inertial>
    <visual>
      <origin rpy="0 0 0" xyz="0 0 0"/>
      <geometry>
        <mesh filename="package://marvin_description/meshes/m6/Link3_R.STL"/>
      </geometry>
      <material name="">
        <color rgba="1 0 0 1"/>
      </material>
    </visual>
    <collision>
      <origin rpy="0 0 0" xyz="0 0 0"/>
      <geometry>
        <mesh filename="package://marvin_description/meshes/m6/Link3_R.STL"/>
      </geometry>
    </collision>
  </link>
  <joint name="Joint3_R" type="revolute">
    <origin rpy="-1.5708 0 0" xyz="0 0.287 0"/>
    <parent link="Link2_R"/>
    <child link="Link3_R"/>
    <axis xyz="0 0 1"/>
    <limit effort="66" lower="-3.1067" upper="3.1067" velocity="3.1416"/>
  </joint>
  <link name="Link4_R">
    <inertial>
      <origin rpy="0 0 0" xyz="0.00850411 -0.04718223 0.00941509"/>
      <mass value="1.6085"/>
      <inertia ixx="0.00580480" ixy="-0.00066669" ixz="-0.00012722" iyy="0.00223807" iyz="0.00070523" izz="0.00533060"/>
    </inertial>
    <visual>
      <origin rpy="0 0 0" xyz="0 0 0"/>
      <geometry>
        <mesh filename="package://marvin_description/meshes/m6/Link4_R.STL"/>
      </geometry>
      <material name="">
        <color rgba="0 1 0 1"/>
      </material>
    </visual>
    <collision>
      <origin rpy="0 0 0" xyz="0 0 0"/>
      <geometry>
        <mesh filename="package://marvin_description/meshes/m6/Link4_R.STL"/>
      </geometry>
    </collision>
  </link>
  <joint name="Joint4_R" type="revolute">
    <origin rpy="-1.5708 0 3.1416" xyz="0.018 0 0"/>
    <parent link="Link3_R"/>
    <child link="Link4_R"/>
    <axis xyz="0 0 1"/>
    <limit effort="66" lower="-2.5307" upper="1.0472" velocity="3.1416"/>
  </joint>
  <link name="Link5_R">
    <inertial>
      <origin rpy="0 0 0" xyz="-0.00051127 -0.00101064 -0.11271739"/>
      <mass value="2.0883"/>
      <inertia ixx="0.00626603" ixy="0.00004009" ixz="-0.00005338" iyy="0.00564387" iyz="0.00006193" izz="0.00243632"/>
    </inertial>
    <visual>
      <origin rpy="0 0 0" xyz="0 0 0"/>
      <geometry>
        <mesh filename="package://marvin_description/meshes/m6/Link5_R.STL"/>
      </geometry>
      <material name="">
        <color rgba="0 0 1 1"/>
      </material>
    </visual>
    <collision>
      <origin rpy="0 0 0" xyz="0 0 0"/>
      <geometry>
        <mesh filename="package://marvin_description/meshes/m6/Link5_R.STL"/>
      </geometry>
    </collision>
  </link>
  <joint name="Joint5_R" type="revolute">
    <origin rpy="-1.5708 0 3.1416" xyz="0.018 -0.314 0"/>
    <parent link="Link4_R"/>
    <child link="Link5_R"/>
    <axis xyz="0 0 1"/>
    <limit effort="18" lower="-3.1067" upper="3.1067" velocity="3.1416"/>
  </joint>
  <link name="Link6_R">
    <inertial>
      <origin rpy="0 0 0" xyz="0.00032659 -0.00531336 0.00030182"/>
      <mass value="0.72496"/>
      <inertia ixx="0.00046040" ixy="-0.00000189" ixz="-0.00000083" iyy="0.00051716" iyz="-0.00000346" izz="0.00042521"/>
    </inertial>
    <visual>
      <origin rpy="0 0 0" xyz="0 0 0"/>
      <geometry>
        <mesh filename="package://marvin_description/meshes/m6/Link6_R.STL"/>
      </geometry>
      <material name="">
        <color rgba="1 0 0 1"/>
      </material>
    </visual>
    <collision>
      <origin rpy="0 0 0" xyz="0 0 0"/>
      <geometry>
        <mesh filename="package://marvin_description/meshes/m6/Link6_R.STL"/>
      </geometry>
    </collision>
  </link>
  <joint name="Joint6_R" type="revolute">
    <origin rpy="1.5708 -1.5708 0" xyz="0 0 0"/>
    <parent link="Link5_R"/>
    <child link="Link6_R"/>
    <axis xyz="0 0 1"/>
    <limit effort="18" lower="-1.0472" upper="1.0472" velocity="3.1416"/>
  </joint>
  <link name="Link7_R">
    <inertial>
      <origin rpy="0 0 0" xyz="-0.00009108 -0.03153255 0.00889371"/>
      <mass value="0.68606"/>
      <inertia ixx="0.00173687" ixy="-0.00000345" ixz="-0.00000116" iyy="0.00089035" iyz="0.00030680" izz="0.00139406"/>
    </inertial>
    <visual>
      <origin rpy="0 0 0" xyz="0 0 0"/>
      <geometry>
        <mesh filename="package://marvin_description/meshes/m6/Link7_R.STL"/>
      </geometry>
      <material name="">
        <color rgba="0 1 0 1"/>
      </material>
    </visual>
    <collision>
      <origin rpy="0 0 0" xyz="0 0 0"/>
      <geometry>
        <mesh filename="package://marvin_description/meshes/m6/Link7_R.STL"/>
      </geometry>
    </collision>
  </link>
  <joint name="Joint7_R" type="revolute">
    <origin rpy="1.5708 -1.5708 0" xyz="0 0 0"/>
    <parent link="Link6_R"/>
    <child link="Link7_R"/>
    <axis xyz="0 0 1"/>
    <limit effort="18" lower="-1.5708" upper="1.5708" velocity="3.1416"/>
  </joint>
  <link name="flange_R"/>
  <joint name="joint_flange_R" type="fixed">
    <origin rpy="1.5708 -1.5708 0" xyz="0.0 -0.088 0.0"/>
    <parent link="Link7_R"/>
    <child link="flange_R"/>
  </joint>
  <!-- Define mesh path as a Xacro property -->
  <!-- base Link -->
  <link name="base_link">
    <inertial>
      <origin rpy="0 0 0" xyz="0.0081994 -5.1239E-06 0.47835"/>
      <mass value="18.846"/>
      <inertia ixx="0.46346" ixy="7.6311E-07" ixz="-0.00053819" iyy="0.46325" iyz="3.466E-06" izz="0.37766"/>
    </inertial>
    <visual>
      <origin rpy="0 0 0" xyz="0 0 0"/>
      <geometry>
        <mesh filename="package://marvin_description/meshes/base/ZJ_Robot_link.STL"/>
      </geometry>
      <material name="">
        <color rgba="0.8 0.8 0.8 1"/>
      </material>
    </visual>
    <collision>
      <origin rpy="0 0 0" xyz="0 0 0"/>
      <geometry>
        <mesh filename="package://marvin_description/meshes/base/ZJ_Robot_link.STL"/>
      </geometry>
    </collision>
  </link>
  <link name="tracking_base_link"/>
  <joint name="base_to_tracking_base" type="fixed">
    <parent link="base_link"/>
    <child link="tracking_base_link"/>
    <origin rpy="0 0 0" xyz="0 0 -0.1"/>
  </joint>
  <link name="camera_rgb_link"/>
  <joint name="camera_joint" type="fixed">
    <parent link="base_link"/>
    <child link="camera_rgb_link"/>
    <origin rpy="-2.3562 0.0 -1.5708" xyz="0.0925 0.0325 1.266"/>
  </joint>

  <link name="camera_left_link"/>
  <joint name="camera_jointL" type="fixed">
    <parent link="base_link"/>
    <child link="camera_left_link"/>
    <origin rpy="-2.3562 0.0 -1.5708" xyz="0.06459 -0.03 1.2516"/>
  </joint>

  <link name="camera_right_link"/>
  <joint name="camera_jointR" type="fixed">
    <parent link="base_link"/>
    <child link="camera_right_link"/>
    <origin rpy="-2.3562 0.0 -1.5708" xyz="0.06459 0.03 1.2516"/>
  </joint>

  <!-- base Link -->
  <joint name="base_to_left_arm" type="fixed">
    <parent link="base_link"/>
    <child link="Base_L"/>
    <origin rpy="-1.57 0 0" xyz="0 0.026 1.121"/>
  </joint>
  <joint name="base_to_right_arm" type="fixed">
    <parent link="base_link"/>
    <child link="Base_R"/>
    <origin rpy="1.57 0 0" xyz="0 -0.026 1.121"/>
  </joint>
  <link name="left_tool"/>
  <joint name="left_tool_joint" type="fixed">
    <parent link="flange_L"/>
    <child link="left_tool"/>
    <origin rpy="3.14 -1.57 0" xyz="0 0.00 .145"/>
  </joint>
  <link name="right_tool"/>
  <joint name="right_tool_joint" type="fixed">
    <parent link="flange_R"/>
    <child link="right_tool"/>
    <origin rpy="-3.14 -1.57 0" xyz="0 -0.00 .145"/>
  </joint>
</robot>
