<?xml version="1.0" ?>
<!-- =================================================================================== -->
<!-- |    This document was autogenerated by xacro from marvin_CCS_m3.urdf.xacro       | -->
<!-- |    EDITING THIS FILE BY HAND IS NOT RECOMMENDED                                 | -->
<!-- =================================================================================== -->
<robot name="marvin_robot">
  <link name="Base_L">
    <inertial>
      <origin rpy="0 0 0" xyz="0.00026267 0.00011932 0.03306285"/>
      <mass value="1.03862143"/>
      <inertia ixx="0.00071755" ixy="0.00000006" ixz="-0.00000688" iyy="0.00071148" iyz="-0.00000335" izz="0.00091518"/>
    </inertial>
    <visual>
      <origin rpy="0 0 0" xyz="0 0 0"/>
      <geometry>
        <mesh filename="package://marvin_description/meshes/m3/Base_L.STL"/>
      </geometry>
      <material name="">
        <color rgba="1 0 0 1"/>
      </material>
    </visual>
    <collision>
      <origin rpy="0 0 0" xyz="0 0 0"/>
      <geometry>
        <mesh filename="package://marvin_description/meshes/m3/Base_L.STL"/>
      </geometry>
    </collision>
  </link>
  <link name="Link1_L">
    <inertial>
      <origin rpy="0 0 0" xyz="0.00005324 0.00445236 -0.03913569"/>
      <mass value="1.77724008"/>
      <inertia ixx="0.00530846" ixy="0.00000240" ixz="-0.00000211" iyy="0.00555862" iyz="0.00029899" izz="0.00133520"/>
    </inertial>
    <visual>
      <origin rpy="0 0 0" xyz="0 0 0"/>
      <geometry>
        <mesh filename="package://marvin_description/meshes/m3/Link1_L.STL"/>
      </geometry>
      <material name="">
        <color rgba="0 1 0 1"/>
      </material>
    </visual>
    <collision>
      <origin rpy="0 0 0" xyz="0 0 0"/>
      <geometry>
        <mesh filename="package://marvin_description/meshes/m3/Link1_L.STL"/>
      </geometry>
    </collision>
  </link>
  <joint name="Joint1_L" type="revolute">
    <origin rpy="0 0 0" xyz="0 0 0.177"/>
    <parent link="Base_L"/>
    <child link="Link1_L"/>
    <axis xyz="0 0 1"/>
    <limit effort="66" lower="-3.1067" upper="3.1067" velocity="3.1416"/>
  </joint>
  <link name="Link2_L">
    <inertial>
      <origin rpy="0 0 0" xyz="-0.00010498 0.05321718 0.00787641"/>
      <mass value="1.60894018"/>
      <inertia ixx="0.00632572" ixy="-0.00000592" ixz="0.00000084" iyy="0.00182184" iyz="-0.00069610" izz="0.00594120"/>
    </inertial>
    <visual>
      <origin rpy="0 0 0" xyz="0 0 0"/>
      <geometry>
        <mesh filename="package://marvin_description/meshes/m3/Link2_L.STL"/>
      </geometry>
      <material name="">
        <color rgba="0 0 1 1"/>
      </material>
    </visual>
    <collision>
      <origin rpy="0 0 0" xyz="0 0 0"/>
      <geometry>
        <mesh filename="package://marvin_description/meshes/m3/Link2_L.STL"/>
      </geometry>
    </collision>
  </link>
  <joint name="Joint2_L" type="revolute">
    <origin rpy="1.5708 0 0" xyz="0 0 0"/>
    <parent link="Link1_L"/>
    <child link="Link2_L"/>
    <axis xyz="0 0 1"/>
    <limit effort="66" lower="-2.0944" upper="2.0944" velocity="3.1416"/>
  </joint>
  <link name="Link3_L">
    <inertial>
      <origin rpy="0 0 0" xyz="0.00810489 0.00245578 -0.05500367"/>
      <mass value="1.27082930"/>
      <inertia ixx="0.00491773" ixy="0.00003519" ixz="0.00058367" iyy="0.00519354" iyz="0.00017843" izz="0.00102662"/>
    </inertial>
    <visual>
      <origin rpy="0 0 0" xyz="0 0 0"/>
      <geometry>
        <mesh filename="package://marvin_description/meshes/m3/Link3_L.STL"/>
      </geometry>
      <material name="">
        <color rgba="1 0 0 1"/>
      </material>
    </visual>
    <collision>
      <origin rpy="0 0 0" xyz="0 0 0"/>
      <geometry>
        <mesh filename="package://marvin_description/meshes/m3/Link3_L.STL"/>
      </geometry>
    </collision>
  </link>
  <joint name="Joint3_L" type="revolute">
    <origin rpy="-1.5708 0 0" xyz="0 0.272 0"/>
    <parent link="Link2_L"/>
    <child link="Link3_L"/>
    <axis xyz="0 0 1"/>
    <limit effort="18" lower="-3.1067" upper="3.1067" velocity="3.1416"/>
  </joint>
  <link name="Link4_L">
    <inertial>
      <origin rpy="0 0 0" xyz="0.00709286 -0.03304509 0.00893402"/>
      <mass value="0.96124622"/>
      <inertia ixx="0.00254980" ixy="-0.00032269" ixz="-0.00006345" iyy="0.00107965" iyz="0.00029545" izz="0.00235605"/>
    </inertial>
    <visual>
      <origin rpy="0 0 0" xyz="0 0 0"/>
      <geometry>
        <mesh filename="package://marvin_description/meshes/m3/Link4_L.STL"/>
      </geometry>
      <material name="">
        <color rgba="0 1 0 1"/>
      </material>
    </visual>
    <collision>
      <origin rpy="0 0 0" xyz="0 0 0"/>
      <geometry>
        <mesh filename="package://marvin_description/meshes/m3/Link4_L.STL"/>
      </geometry>
    </collision>
  </link>
  <joint name="Joint4_L" type="revolute">
    <origin rpy="-1.5708 0 3.1416" xyz="0.018 0 0"/>
    <parent link="Link3_L"/>
    <child link="Link4_L"/>
    <axis xyz="0 0 1"/>
    <limit effort="18" lower="-3.1067" upper="3.1067" velocity="3.1416"/>
  </joint>
  <link name="Link5_L">
    <inertial>
      <origin rpy="0 0 0" xyz="-0.00062313 0.00098400 -0.09276174"/>
      <mass value="0.90217469"/>
      <inertia ixx="0.00189248" ixy="-0.00001906" ixz="-0.00002190" iyy="0.00174389" iyz="-0.00000835" izz="0.00075080"/>
    </inertial>
    <visual>
      <origin rpy="0 0 0" xyz="0 0 0"/>
      <geometry>
        <mesh filename="package://marvin_description/meshes/m3/Link5_L.STL"/>
      </geometry>
      <material name="">
        <color rgba="0 0 1 1"/>
      </material>
    </visual>
    <collision>
      <origin rpy="0 0 0" xyz="0 0 0"/>
      <geometry>
        <mesh filename="package://marvin_description/meshes/m3/Link5_L.STL"/>
      </geometry>
    </collision>
  </link>
  <joint name="Joint5_L" type="revolute">
    <origin rpy="-1.5708 0 3.1416" xyz="0.018 -0.256 0"/>
    <parent link="Link4_L"/>
    <child link="Link5_L"/>
    <axis xyz="0 0 1"/>
    <limit effort="6.5" lower="-3.1067" upper="3.1067" velocity="3.1416"/>
  </joint>
  <link name="Link6_L">
    <inertial>
      <origin rpy="0 0 0" xyz="0.00031369 0.00024238 -0.00041391"/>
      <mass value="0.33261055"/>
      <inertia ixx="0.00015388" ixy="0.00000140" ixz="-0.00000029" iyy="0.00015258" iyz="-0.00000262" izz="0.00013812"/>
    </inertial>
    <visual>
      <origin rpy="0 0 0" xyz="0 0 0"/>
      <geometry>
        <mesh filename="package://marvin_description/meshes/m3/Link6_L.STL"/>
      </geometry>
      <material name="">
        <color rgba="1 0 0 1"/>
      </material>
    </visual>
    <collision>
      <origin rpy="0 0 0" xyz="0 0 0"/>
      <geometry>
        <mesh filename="package://marvin_description/meshes/m3/Link6_L.STL"/>
      </geometry>
    </collision>
  </link>
  <joint name="Joint6_L" type="revolute">
    <origin rpy="1.5708 -1.5708 0" xyz="0 0 0"/>
    <parent link="Link5_L"/>
    <child link="Link6_L"/>
    <axis xyz="0 0 1"/>
    <limit effort="6.5" lower="-1.0472" upper="1.0472" velocity="3.1416"/>
  </joint>
  <link name="Link7_L">
    <inertial>
      <origin rpy="0 0 0" xyz="-0.00006959 -0.03969936 0.00413997"/>
      <mass value="0.30535389"/>
      <inertia ixx="0.00058153" ixy="-0.00000009" ixz="-0.00000084" iyy="0.00026536" iyz="0.00005594" izz="0.00048333"/>
    </inertial>
    <visual>
      <origin rpy="0 0 0" xyz="0 0 0"/>
      <geometry>
        <mesh filename="package://marvin_description/meshes/m3/Link7_L.STL"/>
      </geometry>
      <material name="">
        <color rgba="0 1 0 1"/>
      </material>
    </visual>
    <collision>
      <origin rpy="0 0 0" xyz="0 0 0"/>
      <geometry>
        <mesh filename="package://marvin_description/meshes/m3/Link7_L.STL"/>
      </geometry>
    </collision>
  </link>
  <joint name="Joint7_L" type="revolute">
    <origin rpy="1.5708 -1.5708 0" xyz="0 0 0"/>
    <parent link="Link6_L"/>
    <child link="Link7_L"/>
    <axis xyz="0 0 1"/>
    <limit effort="6.5" lower="-1.5708" upper="1.5708" velocity="3.1416"/>
  </joint>
  <link name="flange_L"/>
  <joint name="joint_flange_L" type="fixed">
    <origin rpy="1.5708 -1.5708 0" xyz="0.0 -0.088 0.0"/>
    <parent link="Link7_L"/>
    <child link="flange_L"/>
  </joint>
  <link name="Base_R">
    <inertial>
      <origin rpy="0 0 0" xyz="0.00026267 0.00011932 0.03306285"/>
      <mass value="1.03862143"/>
      <inertia ixx="0.00071755" ixy="0.00000006" ixz="-0.00000688" iyy="0.00071148" iyz="-0.00000335" izz="0.00091518"/>
    </inertial>
    <visual>
      <origin rpy="0 0 0" xyz="0 0 0"/>
      <geometry>
        <mesh filename="package://marvin_description/meshes/m3/Base_R.STL"/>
      </geometry>
      <material name="">
        <color rgba="1 0 0 1"/>
      </material>
    </visual>
    <collision>
      <origin rpy="0 0 0" xyz="0 0 0"/>
      <geometry>
        <mesh filename="package://marvin_description/meshes/m3/Base_R.STL"/>
      </geometry>
    </collision>
  </link>
  <link name="Link1_R">
    <inertial>
      <origin rpy="0 0 0" xyz="0.00005324 0.00445236 -0.03913569"/>
      <mass value="1.77724008"/>
      <inertia ixx="0.00530846" ixy="0.00000240" ixz="-0.00000211" iyy="0.00555862" iyz="0.00029899" izz="0.00133520"/>
    </inertial>
    <visual>
      <origin rpy="0 0 0" xyz="0 0 0"/>
      <geometry>
        <mesh filename="package://marvin_description/meshes/m3/Link1_R.STL"/>
      </geometry>
      <material name="">
        <color rgba="0 1 0 1"/>
      </material>
    </visual>
    <collision>
      <origin rpy="0 0 0" xyz="0 0 0"/>
      <geometry>
        <mesh filename="package://marvin_description/meshes/m3/Link1_R.STL"/>
      </geometry>
    </collision>
  </link>
  <joint name="Joint1_R" type="revolute">
    <origin rpy="0 0 0" xyz="0 0 0.177"/>
    <parent link="Base_R"/>
    <child link="Link1_R"/>
    <axis xyz="0 0 1"/>
    <limit effort="66" lower="-3.1067" upper="3.1067" velocity="3.1416"/>
  </joint>
  <link name="Link2_R">
    <inertial>
      <origin rpy="0 0 0" xyz="-0.00010498 0.05321718 0.00787641"/>
      <mass value="1.60894018"/>
      <inertia ixx="0.00632572" ixy="-0.00000592" ixz="0.00000084" iyy="0.00182184" iyz="-0.00069610" izz="0.00594120"/>
    </inertial>
    <visual>
      <origin rpy="0 0 0" xyz="0 0 0"/>
      <geometry>
        <mesh filename="package://marvin_description/meshes/m3/Link2_R.STL"/>
      </geometry>
      <material name="">
        <color rgba="0 0 1 1"/>
      </material>
    </visual>
    <collision>
      <origin rpy="0 0 0" xyz="0 0 0"/>
      <geometry>
        <mesh filename="package://marvin_description/meshes/m3/Link2_R.STL"/>
      </geometry>
    </collision>
  </link>
  <joint name="Joint2_R" type="revolute">
    <origin rpy="1.5708 0 0" xyz="0 0 0"/>
    <parent link="Link1_R"/>
    <child link="Link2_R"/>
    <axis xyz="0 0 1"/>
    <limit effort="66" lower="-2.0944" upper="2.0944" velocity="3.1416"/>
  </joint>
  <link name="Link3_R">
    <inertial>
      <origin rpy="0 0 0" xyz="0.00810489 0.00245578 -0.05500367"/>
      <mass value="1.27082930"/>
      <inertia ixx="0.00491773" ixy="0.00003519" ixz="0.00058367" iyy="0.00519354" iyz="0.00017843" izz="0.00102662"/>
    </inertial>
    <visual>
      <origin rpy="0 0 0" xyz="0 0 0"/>
      <geometry>
        <mesh filename="package://marvin_description/meshes/m3/Link3_R.STL"/>
      </geometry>
      <material name="">
        <color rgba="1 0 0 1"/>
      </material>
    </visual>
    <collision>
      <origin rpy="0 0 0" xyz="0 0 0"/>
      <geometry>
        <mesh filename="package://marvin_description/meshes/m3/Link3_R.STL"/>
      </geometry>
    </collision>
  </link>
  <joint name="Joint3_R" type="revolute">
    <origin rpy="-1.5708 0 0" xyz="0 0.272 0"/>
    <parent link="Link2_R"/>
    <child link="Link3_R"/>
    <axis xyz="0 0 1"/>
    <limit effort="18" lower="-3.1067" upper="3.1067" velocity="3.1416"/>
  </joint>
  <link name="Link4_R">
    <inertial>
      <origin rpy="0 0 0" xyz="0.00709286 -0.03304509 0.00893402"/>
      <mass value="0.96124622"/>
      <inertia ixx="0.00254980" ixy="-0.00032269" ixz="-0.00006345" iyy="0.00107965" iyz="0.00029545" izz="0.00235605"/>
    </inertial>
    <visual>
      <origin rpy="0 0 0" xyz="0 0 0"/>
      <geometry>
        <mesh filename="package://marvin_description/meshes/m3/Link4_R.STL"/>
      </geometry>
      <material name="">
        <color rgba="0 1 0 1"/>
      </material>
    </visual>
    <collision>
      <origin rpy="0 0 0" xyz="0 0 0"/>
      <geometry>
        <mesh filename="package://marvin_description/meshes/m3/Link4_R.STL"/>
      </geometry>
    </collision>
  </link>
  <joint name="Joint4_R" type="revolute">
    <origin rpy="-1.5708 0 3.1416" xyz="0.018 0 0"/>
    <parent link="Link3_R"/>
    <child link="Link4_R"/>
    <axis xyz="0 0 1"/>
    <limit effort="18" lower="-3.1067" upper="3.1067" velocity="3.1416"/>
  </joint>
  <link name="Link5_R">
    <inertial>
      <origin rpy="0 0 0" xyz="0.00062313 -0.00098400 -0.09276174"/>
      <mass value="0.90217469"/>
      <inertia ixx="0.00189248" ixy="-0.00001906" ixz="0.00002190" iyy="0.00174389" iyz="0.00000835" izz="0.00075080"/>
    </inertial>
    <visual>
      <origin rpy="0 0 0" xyz="0 0 0"/>
      <geometry>
        <mesh filename="package://marvin_description/meshes/m3/Link5_R.STL"/>
      </geometry>
      <material name="">
        <color rgba="0 0 1 1"/>
      </material>
    </visual>
    <collision>
      <origin rpy="0 0 0" xyz="0 0 0"/>
      <geometry>
        <mesh filename="package://marvin_description/meshes/m3/Link5_R.STL"/>
      </geometry>
    </collision>
  </link>
  <joint name="Joint5_R" type="revolute">
    <origin rpy="-1.5708 0 3.1416" xyz="0.018 -0.256 0"/>
    <parent link="Link4_R"/>
    <child link="Link5_R"/>
    <axis xyz="0 0 1"/>
    <limit effort="6.5" lower="-3.1067" upper="3.1067" velocity="3.1416"/>
  </joint>
  <link name="Link6_R">
    <inertial>
      <origin rpy="0 0 0" xyz="-0.00031369 0.00024238 0.00041391"/>
      <mass value="0.33261055"/>
      <inertia ixx="0.00015479" ixy="-0.00000140" ixz="-0.00000029" iyy="0.00015429" iyz="-0.00000262" izz="0.00013902"/>
    </inertial>
    <visual>
      <origin rpy="0 0 0" xyz="0 0 0"/>
      <geometry>
        <mesh filename="package://marvin_description/meshes/m3/Link6_R.STL"/>
      </geometry>
      <material name="">
        <color rgba="1 0 0 1"/>
      </material>
    </visual>
    <collision>
      <origin rpy="0 0 0" xyz="0 0 0"/>
      <geometry>
        <mesh filename="package://marvin_description/meshes/m3/Link6_R.STL"/>
      </geometry>
    </collision>
  </link>
  <joint name="Joint6_R" type="revolute">
    <origin rpy="1.5708 -1.5708 0" xyz="0 0 0"/>
    <parent link="Link5_R"/>
    <child link="Link6_R"/>
    <axis xyz="0 0 1"/>
    <limit effort="6.5" lower="-1.0472" upper="1.0472" velocity="3.1416"/>
  </joint>
  <link name="Link7_R">
    <inertial>
      <origin rpy="0 0 0" xyz="-0.00006959 -0.03969936 0.00413997"/>
      <mass value="0.30535389"/>
      <inertia ixx="0.00058153" ixy="-0.00000009" ixz="-0.00000084" iyy="0.00026536" iyz="0.00005594" izz="0.00048333"/>
    </inertial>
    <visual>
      <origin rpy="0 0 0" xyz="0 0 0"/>
      <geometry>
        <mesh filename="package://marvin_description/meshes/m3/Link7_R.STL"/>
      </geometry>
      <material name="">
        <color rgba="0 1 0 1"/>
      </material>
    </visual>
    <collision>
      <origin rpy="0 0 0" xyz="0 0 0"/>
      <geometry>
        <mesh filename="package://marvin_description/meshes/m3/Link7_R.STL"/>
      </geometry>
    </collision>
  </link>
  <joint name="Joint7_R" type="revolute">
    <origin rpy="1.5708 -1.5708 0" xyz="0 0 0"/>
    <parent link="Link6_R"/>
    <child link="Link7_R"/>
    <axis xyz="0 0 1"/>
    <limit effort="6.5" lower="-1.5708" upper="1.5708" velocity="3.1416"/>
  </joint>
  <link name="flange_R"/>
  <joint name="joint_flange_R" type="fixed">
    <origin rpy="1.5708 -1.5708 0" xyz="0.0 -0.088 0.0"/>
    <parent link="Link7_R"/>
    <child link="flange_R"/>
  </joint>
  <!-- base Link -->
  <link name="base_link">
    <inertial>
      <origin rpy="0 0 0" xyz="-0.00002 -0.00012 0.16134"/>
      <mass value="0.05"/>
      <inertia ixx="0.01932018" ixy="-0.00000029" ixz="-0.00000083" iyy="0.02037062" iyz="0.00005022" izz="0.00398997"/>
    </inertial>
    <visual>
      <origin rpy="0 0 0" xyz="0 0 0"/>
      <geometry>
        <mesh filename="package://marvin_description/meshes/SRS/BASE.STL"/>
      </geometry>
      <material name="baselink_mat">
        <color rgba="1 1 1 1"/>
        <!--<color rgba="0.9 0.6 0.2 1"/>-->
      </material>
    </visual>
    <collision>
      <origin rpy="0 0 0" xyz="0 0 0"/>
      <geometry>
        <mesh filename="package://marvin_description/meshes/SRS/BASE.STL"/>
      </geometry>
    </collision>
  </link>
  <link name="tracking_base_link"/>
  <joint name="base_to_tracking_base" type="fixed">
    <parent link="base_link"/>
    <child link="tracking_base_link"/>
    <origin rpy="0 0 0" xyz="0 0 -1"/>
  </joint>
  <link name="head_left_camera"/>
  <joint name="base_to_head_camera" type="fixed">
    <parent link="base_link"/>
    <child link="head_left_camera"/>
    <origin rpy="-2.44346 0.00 -1.5708" xyz="0.03 0.055 0.53195"/>
  </joint>
  <joint name="base_to_left_arm" type="fixed">
    <parent link="base_link"/>
    <child link="Base_L"/>
    <origin rpy="-1.57 0 0" xyz="0 0.040 0.21895"/>
  </joint>
  <joint name="base_to_right_arm" type="fixed">
    <parent link="base_link"/>
    <child link="Base_R"/>
    <origin rpy="1.57 0 0" xyz="0 -0.040 0.21895"/>
  </joint>
  <link name="left_tool"/>
  <joint name="left_tool_joint" type="fixed">
    <parent link="flange_L"/>
    <child link="left_tool"/>
    <origin rpy="1.57 -1.57 0" xyz="0 0.00 .145"/>
  </joint>
  <link name="right_tool"/>
  <joint name="right_tool_joint" type="fixed">
    <parent link="flange_R"/>
    <child link="right_tool"/>
    <origin rpy="-1.57 -1.57 0" xyz="0 -0.00 .145"/>
  </joint>
</robot>
